<?xml version="1.0" ?>
<!-- =================================================================================== -->
<!-- |    This document was autogenerated by xacro from /pybullet_ros_test/ros_ws/src/pybullet_ros_server/urdf/testbot.xacro | -->
<!-- |    EDITING THIS FILE BY HAND IS NOT RECOMMENDED                                 | -->
<!-- =================================================================================== -->
<robot name="testbot">
  <link name="root_link">
  </link>
  <joint name="base_to_root" type="fixed">
    <parent link="root_link"/>
    <child link="base_link"/>
    <origin rpy="0 0 0" xyz="0 0 0.155"/>
  </joint>
  <link name="base_link">
    <visual>
      <geometry>
        <box size="0.5 0.35 0.25"/>
      </geometry>
      <origin rpy="0 0 0" xyz="0 0 0"/>
      <material name="grey">
        <color rgba="0.6 0.6 0.6 1"/>
      </material>
    </visual>
    <collision>
      <geometry>
        <box size="0.5 0.35 0.25"/>
      </geometry>
      <origin rpy="0 0 0" xyz="0 0 0"/>
    </collision>
    <inertial>
      <mass value="40.0"/>
      <inertia ixx="0.6166666666666667" ixy="0.0" ixz="0.0" iyy="1.0416666666666667" iyz="0.0" izz="1.2416666666666667"/>
    </inertial>
  </link>
  <gazebo reference="base_link">
    <material>Gazebo/RustySteel</material>
  </gazebo>
  <link name="l_f_wheel">
    <visual>
      <geometry>
        <cylinder length="0.05" radius="0.075"/>
      </geometry>
      <origin rpy="1.5707963267948966 0 0" xyz="0 0 0"/>
      <material name="black">
        <color rgba="1 1 1 1"/>
      </material>
    </visual>
    <collision>
      <geometry>
        <cylinder length="0.05" radius="0.075"/>
      </geometry>
      <origin rpy="1.5707963267948966 0 0" xyz="0 0 0"/>
    </collision>
    <inertial>
      <origin xyz="0 0 0"/>
      <mass value="5.0"/>
      <inertia ixx="0.008072916666666666" ixy="0.0" ixz="0.0" iyy="0.014062499999999999" iyz="0.0" izz="0.008072916666666666"/>
    </inertial>
  </link>
  <joint name="base_to_l_f_wheel" type="continuous">
    <parent link="base_link"/>
    <child link="l_f_wheel"/>
    <axis xyz="0 1 0"/>
    <origin rpy="0 0 0" xyz="0.225 0.225 -0.08"/>
  </joint>
  <gazebo reference="l_f_wheel">
    <mu1 value="0.5"/>
    <mu2 value="0.5"/>
    <fdir1 value="0 0 0"/>
    <maxContacts value="1"/>
    <turnGravityOff>false</turnGravityOff>
    <material>Gazebo/DarkGrey</material>
  </gazebo>
  <link name="l_r_wheel">
    <visual>
      <geometry>
        <cylinder length="0.05" radius="0.075"/>
      </geometry>
      <origin rpy="1.5707963267948966 0 0" xyz="0 0 0"/>
      <material name="black">
        <color rgba="1 1 1 1"/>
      </material>
    </visual>
    <collision>
      <geometry>
        <cylinder length="0.05" radius="0.075"/>
      </geometry>
      <origin rpy="1.5707963267948966 0 0" xyz="0 0 0"/>
    </collision>
    <inertial>
      <origin xyz="0 0 0"/>
      <mass value="5.0"/>
      <inertia ixx="0.008072916666666666" ixy="0.0" ixz="0.0" iyy="0.014062499999999999" iyz="0.0" izz="0.008072916666666666"/>
    </inertial>
  </link>
  <joint name="base_to_l_r_wheel" type="continuous">
    <parent link="base_link"/>
    <child link="l_r_wheel"/>
    <axis xyz="0 1 0"/>
    <origin rpy="0 0 0" xyz="-0.225 0.225 -0.08"/>
  </joint>
  <gazebo reference="l_r_wheel">
    <mu1 value="0.5"/>
    <mu2 value="0.5"/>
    <fdir1 value="0 0 0"/>
    <maxContacts value="1"/>
    <turnGravityOff>false</turnGravityOff>
    <material>Gazebo/DarkGrey</material>
  </gazebo>
  <link name="r_f_wheel">
    <visual>
      <geometry>
        <cylinder length="0.05" radius="0.075"/>
      </geometry>
      <origin rpy="1.5707963267948966 0 0" xyz="0 0 0"/>
      <material name="black">
        <color rgba="1 1 1 1"/>
      </material>
    </visual>
    <collision>
      <geometry>
        <cylinder length="0.05" radius="0.075"/>
      </geometry>
      <origin rpy="1.5707963267948966 0 0" xyz="0 0 0"/>
    </collision>
    <inertial>
      <origin xyz="0 0 0"/>
      <mass value="5.0"/>
      <inertia ixx="0.008072916666666666" ixy="0.0" ixz="0.0" iyy="0.014062499999999999" iyz="0.0" izz="0.008072916666666666"/>
    </inertial>
  </link>
  <joint name="base_to_r_f_wheel" type="continuous">
    <parent link="base_link"/>
    <child link="r_f_wheel"/>
    <axis xyz="0 1 0"/>
    <origin rpy="0 0 0" xyz="0.225 -0.225 -0.08"/>
  </joint>
  <gazebo reference="r_f_wheel">
    <mu1 value="0.5"/>
    <mu2 value="0.5"/>
    <fdir1 value="0 0 0"/>
    <maxContacts value="1"/>
    <turnGravityOff>false</turnGravityOff>
    <material>Gazebo/DarkGrey</material>
  </gazebo>
  <link name="r_r_wheel">
    <visual>
      <geometry>
        <cylinder length="0.05" radius="0.075"/>
      </geometry>
      <origin rpy="1.5707963267948966 0 0" xyz="0 0 0"/>
      <material name="black">
        <color rgba="1 1 1 1"/>
      </material>
    </visual>
    <collision>
      <geometry>
        <cylinder length="0.05" radius="0.075"/>
      </geometry>
      <origin rpy="1.5707963267948966 0 0" xyz="0 0 0"/>
    </collision>
    <inertial>
      <origin xyz="0 0 0"/>
      <mass value="5.0"/>
      <inertia ixx="0.008072916666666666" ixy="0.0" ixz="0.0" iyy="0.014062499999999999" iyz="0.0" izz="0.008072916666666666"/>
    </inertial>
  </link>
  <joint name="base_to_r_r_wheel" type="continuous">
    <parent link="base_link"/>
    <child link="r_r_wheel"/>
    <axis xyz="0 1 0"/>
    <origin rpy="0 0 0" xyz="-0.225 -0.225 -0.08"/>
  </joint>
  <gazebo reference="r_r_wheel">
    <mu1 value="0.5"/>
    <mu2 value="0.5"/>
    <fdir1 value="0 0 0"/>
    <maxContacts value="1"/>
    <turnGravityOff>false</turnGravityOff>
    <material>Gazebo/DarkGrey</material>
  </gazebo>
</robot>

